<sdf version="1.6">
  <model name="HumanoidRobot">
    <static>false</static>

    <!-- Torso -->
    <link name="torso">
      <pose>0 0 1 0 0 0</pose>
      <visual name="torso_visual">
        <geometry>
          <box>
            <size>0.4 0.2 0.6</size>
          </box>
        </geometry>
        <material>
          <ambient>0.8 0.8 0.8 1</ambient>
        </material>
      </visual>
      <collision>
        <geometry>
          <box>
            <size>0.4 0.2 0.6</size>
          </box>
        </geometry>
      </collision>
    </link>

    <!-- Head -->
    <link name="head">
      <pose>0 0 1.4 0 0 0</pose>
      <visual name="head_visual">
        <geometry>
          <sphere>
            <radius>0.15</radius>
          </sphere>
        </geometry>
      </visual>
    </link>
    <joint name="neck_joint" type="revolute">
      <parent>torso</parent>
      <child>head</child>
      <axis>
        <xyz>0 0 1</xyz>
        <limit>
          <lower>-1.0</lower>
          <upper>1.0</upper>
        </limit>
      </axis>
    </joint>

    <!-- Arms -->
    <link name="left_arm">
      <pose>-0.25 0 1 0 0 0</pose>
      <visual name="left_arm_visual">
        <geometry>
          <cylinder>
            <radius>0.05</radius>
            <length>0.4</length>
          </cylinder>
        </geometry>
      </visual>
    </link>
    <joint name="left_shoulder_joint" type="revolute">
      <parent>torso</parent>
      <child>left_arm</child>
      <axis>
        <xyz>0 1 0</xyz>
        <limit>
          <lower>-1.57</lower>
          <upper>1.57</upper>
        </limit>
      </axis>
    </joint>

    <!-- Similarly define right arm, legs, feet -->

    <!-- Left Leg -->
    <link name="left_leg">
      <pose>-0.1 0 0.6 0 0 0</pose>
      <visual name="left_leg_visual">
        <geometry>
          <cylinder>
            <radius>0.08</radius>
            <length>0.5</length>
          </cylinder>
        </geometry>
      </visual>
    </link>
    <joint name="left_hip_joint" type="revolute">
      <parent>torso</parent>
      <child>left_leg</child>
      <axis>
        <xyz>0 1 0</xyz>
        <limit>
          <lower>-1.57</lower>
          <upper>1.57</upper>
        </limit>
      </axis>
    </joint>

    <!-- Feet -->
    <link name="left_foot">
      <pose>-0.1 0 0.1 0 0 0</pose>
      <visual name="left_foot_visual">
        <geometry>
          <box>
            <size>0.15 0.08 0.05</size>
          </box>
        </geometry>
      </visual>
    </link>
    <joint name="left_ankle_joint" type="revolute">
      <parent>left_leg</parent>
      <child>left_foot</child>
      <axis>
        <xyz>1 0 0</xyz>
        <limit>
          <lower>-1.57</lower>
          <upper>1.57</upper>
        </limit>
      </axis>
    </joint>

    <!-- Define right leg and foot in similar fashion -->

  </model>
</sdf>
